<mujoco>
  <compiler autolimits="true" meshdir="assets" angle="radian"/>

  <option cone="elliptic" impratio="10"/>

  <asset>
    <mesh name="chasis" scale=".01 .006 .0015"
      vertex=" 9   2   0
              -10  10  10
               9  -2   0
               10  3  -10
               10 -3  -10
              -8   10 -10
              -10 -10  10
              -8  -10 -10
              -5   0   20"/>
    <material name="robot_mat" rgba="0.4 0.4 0.9 1"/>
    <material name="metal" rgba="0.58 0.58 0.58 1"/>
    <material name="silicone" rgba="0.1882 0.1882 0.1882 1"/>
    <material name="gray" rgba="0.4627 0.4627 0.4627 1"/>
    <material name="black" rgba="0.149 0.149 0.149 1"/>

    <mesh class="2f85" file="base_mount.stl"/>
    <mesh class="2f85" file="base.stl"/>
    <mesh class="2f85" file="driver.stl"/>
    <mesh class="2f85" file="coupler.stl"/>
    <mesh class="2f85" file="follower.stl"/>
    <mesh class="2f85" file="pad.stl"/>
    <mesh class="2f85" file="silicone_pad.stl"/>
    <mesh class="2f85" file="spring_link.stl"/>
  </asset>

  <default>
    <joint damping=".03" actuatorfrcrange="-0.5 0.5"/>
    <default class="wheel">
      <geom type="cylinder" size=".03 .01" rgba=".5 .5 1 1"/>
    </default>
    <default class="decor">
      <site type="box" rgba=".5 1 .5 1"/>
    </default>
    <default class="2f85">
      <mesh scale="0.001 0.001 0.001"/>
      <general biastype="affine"/>

      <joint axis="1 0 0"/>
      <default class="driver">
        <joint range="0 0.8" armature="0.005" damping="0.1" solimplimit="0.95 0.99 0.001" solreflimit="0.005 1"/>
      </default>
      <default class="follower">
        <joint range="-0.872664 0.872664" armature="0.001" pos="0 -0.018 0.0065" solimplimit="0.95 0.99 0.001" solreflimit="0.005 1"/>
      </default>
      <default class="spring_link">
        <joint range="-0.29670597283 0.8" armature="0.001" stiffness="0.05" springref="2.62" damping="0.00125"/>
      </default>
      <default class="coupler">
        <joint range="-1.57 0" armature="0.001" solimplimit="0.95 0.99 0.001" solreflimit="0.005 1"/>
      </default>

      <default class="visual">
        <geom type="mesh" contype="0" conaffinity="0" group="2"/>
      </default>
      <default class="collision">
        <geom type="mesh" group="3"/>
        <default class="pad_box1">
          <geom mass="0" type="box" pos="0 -0.0026 0.028125" size="0.011 0.004 0.009375" friction="0.7"
            solimp="0.95 0.99 0.001" solref="0.004 1" priority="1" rgba="0.55 0.55 0.55 1"/>
        </default>
        <default class="pad_box2">
          <geom mass="0" type="box" pos="0 -0.0026 0.009375" size="0.011 0.004 0.009375" friction="0.6"
            solimp="0.95 0.99 0.001" solref="0.004 1" priority="1" rgba="0.45 0.45 0.45 1"/>
        </default>
      </default>
    </default>
  </default>

  <worldbody>

    <body name="car" pos="0 0 .03">
      <freejoint/>
      <inertial mass="1.0" pos="0 0 0" diaginertia="0.01 0.01 0.01"/>
      <light name="top light" pos="0 0 2" mode="trackcom" diffuse=".4 .4 .4"/>
      <geom name="cylinder" type="cylinder" size="0.08 0.02" material="robot_mat"/>
      <geom name="front wheel" pos=".08 0 -.015" type="sphere" size=".015" condim="1" priority="1"/>
      <light name="front light" pos=".1 0 .02" dir="2 0 -1" diffuse="1 1 1"/>
      <body name="left wheel" pos="-.00 .06 0" zaxis="0 1 0">
        <joint name="left"/>
        <inertial mass="0.05" pos="0 0 0" diaginertia="0.0001 0.0001 0.0001"/>
        <geom class="wheel"/>
        <site class="decor" size=".006 .025 .012"/>
        <site class="decor" size=".025 .006 .012"/>
      </body>
      <body name="right wheel" pos="-.00 -.06 0" zaxis="0 1 0">
        <joint name="right"/>
        <inertial mass="0.05" pos="0 0 0" diaginertia="0.0001 0.0001 0.0001"/>
        <geom class="wheel"/>
        <site class="decor" size=".006 .025 .012"/>
        <site class="decor" size=".025 .006 .012"/>
      </body>
      <body name="base_mount" pos="0 0 0.017" quat="0.500 0.500 0.500 0.500" childclass="2f85">
        <geom class="visual" mesh="base_mount" material="black"/>
        <geom class="collision" mesh="base_mount"/>
        <body name="base" pos="0 0 0.0038" quat="1 0 0 -1">
          <inertial mass="0.777441" pos="0 -2.70394e-05 0.0354675" quat="1 -0.00152849 0 0"
            diaginertia="0.000260285 0.000225381 0.000152708"/>
          <geom class="visual" mesh="base" material="black"/>
          <geom class="collision" mesh="base"/>
          <site name="pinch" pos="0 0 0.145" type="sphere" group="5" rgba="0.9 0.9 0.9 1" size="0.005"/>
          <body name="right_driver" pos="0 0.0306011 0.054904">
            <inertial mass="0.00899563" pos="2.96931e-12 0.0177547 0.00107314" quat="0.681301 0.732003 0 0"
              diaginertia="1.72352e-06 1.60906e-06 3.22006e-07"/>
            <joint name="right_driver_joint" class="driver"/>
            <geom class="visual" mesh="driver" material="gray"/>
            <geom class="collision" mesh="driver"/>
            <body name="right_coupler" pos="0 0.0315 -0.0041">
              <inertial mass="0.0140974" pos="0 0.00301209 0.0232175" quat="0.705636 -0.0455904 0.0455904 0.705636"
                diaginertia="4.16206e-06 3.52216e-06 8.88131e-07"/>
              <joint name="right_coupler_joint" class="coupler"/>
              <geom class="visual" mesh="coupler" material="black"/>
              <geom class="collision" mesh="coupler"/>
            </body>
          </body>
          <body name="right_spring_link" pos="0 0.0132 0.0609">
            <inertial mass="0.0221642" pos="-8.65005e-09 0.0181624 0.0212658" quat="0.663403 -0.244737 0.244737 0.663403"
              diaginertia="8.96853e-06 6.71733e-06 2.63931e-06"/>
            <joint name="right_spring_link_joint" class="spring_link"/>
            <geom class="visual" mesh="spring_link" material="black"/>
            <geom class="collision" mesh="spring_link"/>
            <body name="right_follower" pos="0 0.055 0.0375">
              <inertial mass="0.0125222" pos="0 -0.011046 0.0124786" quat="1 0.1664 0 0"
                diaginertia="2.67415e-06 2.4559e-06 6.02031e-07"/>
              <joint name="right_follower_joint" class="follower"/>
              <geom class="visual" mesh="follower" material="black"/>
              <geom class="collision" mesh="follower"/>
              <body name="right_pad" pos="0 -0.0189 0.01352">
                <geom class="pad_box1" name="right_pad1"/>
                <geom class="pad_box2" name="right_pad2"/>
                <inertial mass="0.0035" pos="0 -0.0025 0.0185" quat="0.707107 0 0 0.707107"
                  diaginertia="4.73958e-07 3.64583e-07 1.23958e-07"/>
                <geom class="visual" mesh="pad"/>
                <body name="right_silicone_pad">
                  <geom class="visual" mesh="silicone_pad" material="black"/>
                </body>
              </body>
            </body>
          </body>
          <body name="left_driver" pos="0 -0.0306011 0.054904" quat="0 0 0 1">
            <inertial mass="0.00899563" pos="0 0.0177547 0.00107314" quat="0.681301 0.732003 0 0"
              diaginertia="1.72352e-06 1.60906e-06 3.22006e-07"/>
            <joint name="left_driver_joint" class="driver"/>
            <geom class="visual" mesh="driver" material="gray"/>
            <geom class="collision" mesh="driver"/>
            <body name="left_coupler" pos="0 0.0315 -0.0041">
              <inertial mass="0.0140974" pos="0 0.00301209 0.0232175" quat="0.705636 -0.0455904 0.0455904 0.705636"
                diaginertia="4.16206e-06 3.52216e-06 8.88131e-07"/>
              <joint name="left_coupler_joint" class="coupler"/>
              <geom class="visual" mesh="coupler" material="black"/>
              <geom class="collision" mesh="coupler"/>
            </body>
          </body>
          <body name="left_spring_link" pos="0 -0.0132 0.0609" quat="0 0 0 1">
            <inertial mass="0.0221642" pos="-8.65005e-09 0.0181624 0.0212658" quat="0.663403 -0.244737 0.244737 0.663403"
              diaginertia="8.96853e-06 6.71733e-06 2.63931e-06"/>
            <joint name="left_spring_link_joint" class="spring_link"/>
            <geom class="visual" mesh="spring_link" material="black"/>
            <geom class="collision" mesh="spring_link"/>
            <body name="left_follower" pos="0 0.055 0.0375">
              <inertial mass="0.0125222" pos="0 -0.011046 0.0124786" quat="1 0.1664 0 0"
                diaginertia="2.67415e-06 2.4559e-06 6.02031e-07"/>
              <joint name="left_follower_joint" class="follower"/>
              <geom class="visual" mesh="follower" material="black"/>
              <geom class="collision" mesh="follower"/>
              <body name="left_pad" pos="0 -0.0189 0.01352">
                <geom class="pad_box1" name="left_pad1"/>
                <geom class="pad_box2" name="left_pad2"/>
                <inertial mass="0.0035" pos="0 -0.0025 0.0185" quat="1 0 0 1"
                  diaginertia="4.73958e-07 3.64583e-07 1.23958e-07"/>
                <geom class="visual" mesh="pad"/>
                <body name="left_silicone_pad">
                  <geom class="visual" mesh="silicone_pad" material="black"/>
                </body>
              </body>
            </body>
          </body>
        </body>
      </body>
      
    </body>
  </worldbody>

  <tendon>
    <fixed name="forward">
      <joint joint="left" coef=".5"/>
      <joint joint="right" coef=".5"/>
    </fixed>
    <fixed name="turn">
      <joint joint="left" coef="-.5"/>
      <joint joint="right" coef=".5"/>
    </fixed>
    <fixed name="split">
      <joint joint="right_driver_joint" coef="0.5"/>
      <joint joint="left_driver_joint" coef="0.5"/>
    </fixed>
  </tendon>

  <equality>
    <connect anchor="0 0 0" body1="right_follower" body2="right_coupler" solimp="0.95 0.99 0.001" solref="0.005 1"/>
    <connect anchor="0 0 0" body1="left_follower" body2="left_coupler" solimp="0.95 0.99 0.001" solref="0.005 1"/>
    <joint joint1="right_driver_joint" joint2="left_driver_joint" polycoef="0 1 0 0 0" solimp="0.95 0.99 0.001"
      solref="0.005 1"/>
  </equality>

  <actuator>
    <motor name="forward" tendon="forward" ctrlrange="-1 1" />
    <motor name="turn" tendon="turn" ctrlrange="-1 1"/>
    <general class="2f85" name="fingers_actuator" tendon="split" forcerange="-5 5" ctrlrange="0 255"
      gainprm="0.3137255 0 0" biasprm="0 -100 -10"/>
  </actuator>

  <sensor>
    <jointactuatorfrc name="right" joint="right"/>
    <jointactuatorfrc name="left" joint="left"/>
  </sensor>
</mujoco>
